Workbook

Sheet Summary
A1: Progress | B1: Total | C1: Done | D1: Writing | E1: To do
A2: Latest Jobs | B2: =COUNTIF('All Posts – To Write'!$B$2:$B$198,A2) | C2: =COUNTIFS('All Posts – To Write'!$B$2:$B$198,A2,'All Posts – To Write'!$H$2:$H$198,"Done") | D2: =COUNTIFS('All Posts – To Write'!$B$2:$B$198,A2,'All Posts – To Write'!$H$2:$H$198,"Writing") | E2: =COUNTIFS('All Posts – To Write'!$B$2:$B$198,A2,'All Posts – To Write'!$H$2:$H$198,"To do")
A3: Result | B3: =COUNTIF('All Posts – To Write'!$B$2:$B$198,A3) | C3: =COUNTIFS('All Posts – To Write'!$B$2:$B$198,A3,'All Posts – To Write'!$H$2:$H$198,"Done") | D3: =COUNTIFS('All Posts – To Write'!$B$2:$B$198,A3,'All Posts – To Write'!$H$2:$H$198,"Writing") | E3: =COUNTIFS('All Posts – To Write'!$B$2:$B$198,A3,'All Posts – To Write'!$H$2:$H$198,"To do")
A4: Admit Card | B4: =COUNTIF('All Posts – To Write'!$B$2:$B$198,A4) | C4: =COUNTIFS('All Posts – To Write'!$B$2:$B$198,A4,'All Posts – To Write'!$H$2:$H$198,"Done") | D4: =COUNTIFS('All Posts – To Write'!$B$2:$B$198,A4,'All Posts – To Write'!$H$2:$H$198,"Writing") | E4: =COUNTIFS('All Posts – To Write'!$B$2:$B$198,A4,'All Posts – To Write'!$H$2:$H$198,"To do")
A5: Answer Key | B5: =COUNTIF('All Posts – To Write'!$B$2:$B$198,A5) | C5: =COUNTIFS('All Posts – To Write'!$B$2:$B$198,A5,'All Posts – To Write'!$H$2:$H$198,"Done") | D5: =COUNTIFS('All Posts – To Write'!$B$2:$B$198,A5,'All Posts – To Write'!$H$2:$H$198,"Writing") | E5: =COUNTIFS('All Posts – To Write'!$B$2:$B$198,A5,'All Posts – To Write'!$H$2:$H$198,"To do")
A6: Syllabus | B6: =COUNTIF('All Posts – To Write'!$B$2:$B$198,A6) | C6: =COUNTIFS('All Posts – To Write'!$B$2:$B$198,A6,'All Posts – To Write'!$H$2:$H$198,"Done") | D6: =COUNTIFS('All Posts – To Write'!$B$2:$B$198,A6,'All Posts – To Write'!$H$2:$H$198,"Writing") | E6: =COUNTIFS('All Posts – To Write'!$B$2:$B$198,A6,'All Posts – To Write'!$H$2:$H$198,"To do")
A7: Admission | B7: =COUNTIF('All Posts – To Write'!$B$2:$B$198,A7) | C7: =COUNTIFS('All Posts – To Write'!$B$2:$B$198,A7,'All Posts – To Write'!$H$2:$H$198,"Done") | D7: =COUNTIFS('All Posts – To Write'!$B$2:$B$198,A7,'All Posts – To Write'!$H$2:$H$198,"Writing") | E7: =COUNTIFS('All Posts – To Write'!$B$2:$B$198,A7,'All Posts – To Write'!$H$2:$H$198,"To do")
A8: Certificate | B8: =COUNTIF('All Posts – To Write'!$B$2:$B$198,A8) | C8: =COUNTIFS('All Posts – To Write'!$B$2:$B$198,A8,'All Posts – To Write'!$H$2:$H$198,"Done") | D8: =COUNTIFS('All Posts – To Write'!$B$2:$B$198,A8,'All Posts – To Write'!$H$2:$H$198,"Writing") | E8: =COUNTIFS('All Posts – To Write'!$B$2:$B$198,A8,'All Posts – To Write'!$H$2:$H$198,"To do")
A9: Outsourcing | B9: =COUNTIF('All Posts – To Write'!$B$2:$B$198,A9) | C9: =COUNTIFS('All Posts – To Write'!$B$2:$B$198,A9,'All Posts – To Write'!$H$2:$H$198,"Done") | D9: =COUNTIFS('All Posts – To Write'!$B$2:$B$198,A9,'All Posts – To Write'!$H$2:$H$198,"Writing") | E9: =COUNTIFS('All Posts – To Write'!$B$2:$B$198,A9,'All Posts – To Write'!$H$2:$H$198,"To do")
A10: Important | B10: =COUNTIF('All Posts – To Write'!$B$2:$B$198,A10) | C10: =COUNTIFS('All Posts – To Write'!$B$2:$B$198,A10,'All Posts – To Write'!$H$2:$H$198,"Done") | D10: =COUNTIFS('All Posts – To Write'!$B$2:$B$198,A10,'All Posts – To Write'!$H$2:$H$198,"Writing") | E10: =COUNTIFS('All Posts – To Write'!$B$2:$B$198,A10,'All Posts – To Write'!$H$2:$H$198,"To do")
A11: All sections | B11: =SUM(B2:B10) | C11: =SUM(C2:C10) | D11: =SUM(D2:D10) | E11: =SUM(E2:E10)
A13: Detailed job rows (Latest Jobs sheet) | B13: =COUNTA('Latest Jobs'!B2:B31)
A14: …of which still open today | B14: =COUNTIF('Latest Jobs'!I2:I31,"Open")
A15: Total vacancies in open jobs | B15: =SUMIFS('Latest Jobs'!E2:E31,'Latest Jobs'!I2:I31,"Open")

Sheet Latest Jobs
A1: # | B1: Post name | C1: Organisation | D1: Advt. no. | E1: Total posts | F1: Post date | G1: Application starts | H1: Last date | I1: Status | J1: Fee last date | K1: Exam date | L1: All important dates | M1: Application fee | N1: Fee payment mode | O1: Min age | P1: Max age | Q1: Age note / as on | R1: Vacancy (post – count) | S1: Eligibility | T1: Category-wise vacancy | U1: Pay / stipend | V1: Selection process | W1: Official links | X1: YOUR short info (write) | Y1: YOUR how to apply (write) | Z1: YOUR FAQs (write) | AA1: Written?
A2: 1 | B2: Indian Army TGC-145 (July 2027 batch) Online Form 2026 | C2: Indian Army | D2: TGC-145 | E2: 30 | F2: 07 Oct 2026 | G2: 30 Sep 2026 | H2: 46324 | I2: =IF(H2="","",IF(H2<TODAY(),"Closed","Open")) | J2: No fee | K2: SSB interview as per Army schedule | L2: Application starts: 30 Sep 2026 Last date: 2026-10-29 Fee last date: No fee Exam: SSB interview as per Army schedule | M2: All candidates: No fee | O2: 20 years | P2: 27 years | Q2: As on 01 Jan 2027; unmarried men only | R2: Civil / Building Construction – 8 Computer Science / IT / M.Sc CS – 6 Mechanical / Production / Automobile – 6 Electronics & Telecom – 6 Electrical / EEE – 2 Misc. engineering streams – 2 | S2: Civil / Building Construction – B.E./B.Tech in branch (final-year can apply) Computer Science / IT / M.Sc CS – B.E./B.Tech or M.Sc in branch Mechanical / Production / Automobile – B.E./B.Tech in branch Electronics & Telecom – B.E./B.Tech in branch Electrical / EEE – B.E./B.Tech in branch Misc. engineering streams – B.E./B.Tech in branch | U2: See official notification | W2: Apply online: https://joinindianarmy.nic.in/ Join Indian Army official website: https://joinindianarmy.nic.in/index.htm | X2: EXAMPLE – replace: [Organisation] has opened [N] posts. Apply online between [start] and [last date]. Check age and qualification below. | Y2: EXAMPLE – 1. Read the notification 2. Register on the official site 3. Fill form & upload documents 4. Pay fee & print | Z2: EXAMPLE – Q: What is the last date? A: [date]. | AA2: No
A3: 2 | B3: NTA UGC NET December 2026 Online Form | C3: National Testing Agency (NTA) | F3: 13 Oct 2026 | G3: 08 Oct 2026 | H3: 46326 | I3: =IF(H3="","",IF(H3<TODAY(),"Closed","Open")) | J3: 31 Oct 2026 (with ₹500 late fee; normal last date 28 Oct) | K3: 14–19 Dec 2026 | L3: Application starts: 08 Oct 2026 Last date: 2026-10-31 Fee last date: 31 Oct 2026 (with ₹500 late fee; normal last date 28 Oct) Exam: 14–19 Dec 2026 | M3: General: ₹1,150 EWS / OBC: ₹600 SC / ST / PwBD: ₹325 Late fee: ₹500 | N3: Debit/credit card, net banking, UPI | O3: No minimum | P3: 30 years for JRF; no limit for Assistant Professor / PhD | Q3: As on 01 Dec 2026 | R3: JRF / Assistant Professor / PhD admission – — | S3: JRF / Assistant Professor / PhD admission – Master’s degree with 55% (50% for reserved) | U3: See official notification | W3: Apply online: https://examinationservices.nic.in/ExamSys27/root/home.aspx?enc=Ei4cajBkK1gZSfgr53ImFV%2FyIzhTZHBze3wooSg9DjjOvzupXmjixBOc0vZyJQ9v Information bulletin (PDF): https://cdnbbsr.s3waas.gov.in/s301eee509ee2f68dc6014898c309e86bf/uploads/2026/10/202610081852912625.pdf UGC NET official website: https://ugcnet.nta.nic.in/ | AA3: No
A4: 3 | B4: LIC Housing Finance Apprentice Recruitment 2026 | C4: LIC Housing Finance Limited | D4: Batch 10 | E4: 232 | F4: 23 Oct 2026 | G4: 20 Oct 2026 | H4: 46327 | I4: =IF(H4="","",IF(H4<TODAY(),"Closed","Open")) | J4: 01 Nov 2026 | K4: 07 Nov 2026 | L4: Application starts: 20 Oct 2026 Last date: 2026-11-01 Fee last date: 01 Nov 2026 Exam: 07 Nov 2026 | M4: General / OBC / EWS (male): ₹800 General / OBC / EWS (female): ₹600 SC / ST / PwBD: ₹200 | N4: Debit/credit card, net banking, UPI | O4: 20 years | P4: 25 years | Q4: As on 01 Oct 2026 | R4: Apprentice – 232 | S4: Apprentice – Graduate in any stream | U4: See official notification | W4: Register on NATS: https://nats.education.gov.in/student_type.php Notification (PDF): https://cdn.lichousing.com/2026/10/Apprentecis-Advertisement-Notification-Batch-10.pdf LIC HFL careers: https://www.lichousing.com/careers | AA4: No
A5: 4 | B5: BPSC School Teacher TRE 4.0 Recruitment 2026 | C5: Bihar Public Service Commission (BPSC) | D5: 15/2026 | E5: 33320 | F5: 26 Oct 2026 | G5: 25 Sep 2026 | H5: 46328 | I5: =IF(H5="","",IF(H5<TODAY(),"Closed","Open")) | J5: 02 Nov 2026 | K5: To be announced | L5: Application starts: 25 Sep 2026 Last date: 2026-11-02 Fee last date: 02 Nov 2026 Exam: To be announced | M5: All categories: ₹100 | N5: Online | O5: 18 years (21 for TGT/PGT) | P5: 37 years (men), 40 years (women) | Q5: Relaxation as per Bihar rules | R5: Primary teacher (Class 1–5) – 3847 Middle school teacher (Class 6–8) – 8563 Secondary teacher (Class 9–10) – 4370 Senior secondary teacher (Class 11–12) – 16540 | S5: Primary teacher (Class 1–5) – 12th + D.El.Ed/B.El.Ed + STET/CTET Paper I Middle school teacher (Class 6–8) – Graduate + D.El.Ed/B.Ed + CTET/STET Paper II Secondary teacher (Class 9–10) – Graduate/PG in subject + B.Ed + STET Senior secondary teacher (Class 11–12) – PG in subject + B.Ed + STET | T5: See district-wise vacancy PDFs | U5: See official notification | W5: Apply online (OTR login): https://bpsconline.bihar.gov.in/candidate/login Detailed advertisement (PDF): https://bpsc.bihar.gov.in/wp-content/uploads/BPSC_content/Notices/Advertisement-152026-TRE-4.0_BPSC-20260922-dbsf04.pdf BPSC official website: https://bpsc.bihar.gov.in/ | AA5: No
A6: 5 | B6: DSSSB Delhi District Courts Various Post Recruitment 2026 | C6: Delhi Subordinate Services Selection Board (DSSSB) | D6: 04/2026 | E6: 641 | G6: 06 October 2026 | H6: 46330 | I6: =IF(H6="","",IF(H6<TODAY(),"Closed","Open")) | K6: To be announced | L6: Apply online starts: 06 October 2026 Last date to apply: 04 November 2026 Exam date: To be announced | M6: General / OBC / EWS: ₹100 SC / ST / PwBD / Female: No fee | O6: 18 years | P6: 27 years (as on 01 June 2026; varies by post) | R6: Personal Assistant (District Courts) – 189 Junior Judicial Assistant (District Courts) – 151 Peon / Orderly / Dak Peon (District Courts) – 139 Process Server (District Courts) – 91 Senior Personal Assistant (District Courts) – 27 Junior Judicial Assistant (Family Courts) – 23 Personal Assistant (Family Courts) – 17 Peon / Orderly (Family Courts) – 3 Process Server (Family Courts) – 1 | S6: Senior PA / PA – Graduate + shorthand 110 wpm + typing 40 wpm Junior Judicial Assistant – Graduate + computer typing 40 wpm Process Server – 10th pass + LMV licence + 2 years driving Peon / Orderly / Dak Peon – 10th pass | U6: Pay: See official notification | V6: Written exam Skill / typing test (where required) Document verification | W6: Apply online: https://dsssbonline.nic.in/ DSSSB official website: https://dsssb.delhi.gov.in/ | AA6: No
A7: 6 | B7: UPESSC UP Assistant Teacher (Primary) Recruitment 2026 | C7: UP Education Service Selection Commission (UPESSC) | D7: 05/2026 | E7: 12405 | F7: 28 Oct 2026 | G7: 16 Sep 2026 | H7: 46330 | I7: =IF(H7="","",IF(H7<TODAY(),"Closed","Open")) | J7: 04 Nov 2026 | K7: 03–04 Dec 2026 | L7: Application starts: 16 Sep 2026 Last date: 2026-11-04 Fee last date: 04 Nov 2026 Exam: 03–04 Dec 2026 | M7: General / OBC / EWS: ₹1,000 SC / ST: ₹500 PwBD: ₹300 | N7: Debit/credit card, net banking, UPI | O7: 21 years | P7: 40 years | Q7: As on 01 Jul 2026 | R7: Assistant Teacher – urban primary schools – 11508 Assistant Teacher – aided primary schools – 897 | S7: Assistant Teacher – urban primary schools – Graduate + D.El.Ed/BTC or B.El.Ed Assistant Teacher – aided primary schools – Graduate + D.El.Ed/BTC or B.El.Ed + Primary TET | T7: Urban: UR 4746 · OBC 3069 · EWS 1116 · SC 2379 · ST 198 Aided: UR 378 · OBC 164 · EWS 7 · SC 348 | U7: See official notification | W7: Registration: https://apply.upessc.org/register Date-extension notice (PDF): https://upessc.up.gov.in/Notice/4b1f-907a-4508-5c3a-0c65.pdf UPESSC official website: https://upessc.up.gov.in/ | AA7: No
A8: 7 | B8: TNPSC Group IV (CCSE-IV) Recruitment 2026 | C8: Tamil Nadu Public Service Commission (TNPSC) | D8: 11/2026 | E8: 6574 | G8: 06 October 2026 | H8: 46331 | I8: =IF(H8="","",IF(H8<TODAY(),"Closed","Open")) | K8: 10 January 2027 (9:30 AM – 12:30 PM) | L8: Notification released: 06 October 2026 Apply online starts: 06 October 2026 Last date to apply: 05 November 2026 Correction window: 09 – 11 November 2026 Exam date: 10 January 2027 (9:30 AM – 12:30 PM) | M8: One-time registration: ₹150 Examination fee: ₹100 (exemptions as per rules) | O8: 18 years | P8: Varies by post — see notification | Q8: As per TN government rules | R8: Junior Assistant (Non-Security) – 2600 – 2610 Typist – 2200 – 856 Junior Assistant (Accounts) – 3848 – 422 Typist – 4200 – 377 Village Administrative Officer – 2025 – 291 Typist – 3844 – 260 Junior Assistant (Non-Security) – 4600 – 252 Steno-Typist Gr III – 2300 – 209 Steno-Typist Gr III – 4300 – 145 Other posts (see notification) – 1152 | S8: Most posts (VAO, Junior Assistant, Bill Collector) – SSLC / 10th pass Typist / Steno posts – 10th pass + Government Technical Exam in typewriting / shorthand Some posts – Degree or specific technical qualification — check post code | U8: Most posts: Level 8 / Level 10 (TN pay matrix) — varies by post | V8: Single OMR written exam Certificate verification Counselling | W8: Apply online: https://apply.tnpscexams.in/ TNPSC official website: https://tnpsc.gov.in/ | AA8: No
A9: 8 | B9: RRB NTPC Graduate Level Recruitment 2026 | C9: Railway Recruitment Board (RRB) | D9: CEN 06/2026 | E9: 3477 | G9: 08 October 2026 | H9: 46332 | I9: =IF(H9="","",IF(H9<TODAY(),"Closed","Open")) | J9: 06 November 2026 | K9: To be announced | L9: Notification released: 22 September 2026 Apply online starts: 08 October 2026 Last date to apply: 06 November 2026 Last date for fee payment: 06 November 2026 Exam date: To be announced | M9: General / OBC / EWS: ₹500 (₹400 refunded after CBT-1) SC / ST / EBC / Female: ₹250 (refunded after CBT-1) | O9: 18 years | P9: 33 years | Q9: As per Railway rules | R9: NTPC Graduate Level posts (all) – 3477 | S9: Chief Commercial cum Ticket Supervisor – Graduate (any discipline) Station Master – Graduate (any discipline) Goods Train Manager – Graduate (any discipline) Junior Accounts Assistant cum Typist – Graduate + computer typing in English or Hindi Senior Clerk cum Typist – Graduate + computer typing in English or Hindi Traffic Assistant – Graduate (any discipline) | U9: Pay level: Level 5 and Level 6 (7th CPC) | V9: CBT-1 CBT-2 Typing / aptitude test (post-wise) Document verification Medical examination | W9: Apply online: https://www.rrbapply.gov.in/ Indian Railways official website: https://indianrailways.gov.in/ | AA9: No
A10: 9 | B10: RRC NWR Act Apprentice Recruitment 2026 | C10: RRC North Western Railway, Jaipur | D10: 04/2026 (NWR/AA) | E10: 2008 | G10: 07 October 2026 | H10: 46332 | I10: =IF(H10="","",IF(H10<TODAY(),"Closed","Open")) | L10: Notification released: 01 October 2026 Apply online starts: 07 October 2026 Last date to apply: 06 November 2026 | M10: General / OBC / EWS: ₹100 SC / ST / PwBD / Women: No fee | O10: 15 years | P10: 24 years | Q10: As per Railway rules | R10: General – 845 OBC – 543 EWS – 182 SC – 295 ST – 143 | S10: All trades – 10th pass with at least 50% marks + ITI in the relevant trade | U10: Stipend: As per Railway Board / Apprentices Act rules | V10: Merit list (no written exam) Document verification | W10: Official notification (PDF): https://rrcjaipur.in/storeWebFiles/1005_12061494.PDF RRC Jaipur official website / apply: https://www.rrcjaipur.in/ | AA10: No
A11: 10 | B11: NLC Apprentice Recruitment 2026 | C11: NLC India Limited | D11: L&DC/04/2026 | E11: 1067 | G11: 21 October 2026 | H11: 46335 | I11: =IF(H11="","",IF(H11<TODAY(),"Closed","Open")) | L11: Notification released: 21 October 2026 Apply online starts: 21 October 2026 Last date to apply: 09 November 2026 (5 PM) Selection list (trade): 23 November 2026 (tentative) Selection list (graduate): 25 November 2026 (tentative) | M11: Application fee: Not mentioned in notification | O11: 18 years | Q11: As per rules | R11: ITI Trade Apprentice (10 trades) – 700 Graduate (Non-Engg) Apprentice – 367 | S11: Trade apprentice – ITI in the relevant trade Graduate apprentice – Regular B.Com / BBA / B.Sc / BCA / B.Pharm / B.Sc Nursing passed 2022–2026 | U11: Stipend: ₹12,000 – ₹16,678 per month (12 months training) | V11: Merit based on marks in the qualifying exam | W11: Apply online: https://web.nlcindia.in/ldcappexiti/ Official notification: https://www.nlcindia.in/nlcilapi/cmp/static/downloadfile/93369 NLC India official website: https://www.nlcindia.in/ | AA11: No
A12: 11 | B12: GSSSB Food Safety Officer Recruitment 2026 | C12: Gujarat Subordinate Services Selection Board (GSSSB) | D12: 465/202627 | E12: 84 | G12: 27 October 2026 | H12: 46336 | I12: =IF(H12="","",IF(H12<TODAY(),"Closed","Open")) | K12: To be announced | L12: Notification released: 27 October 2026 Apply online starts: 27 October 2026 Last date to apply: 10 November 2026 Exam date: To be announced | M12: Unreserved: ₹500 Reserved categories: ₹400 | O12: 18 years | P12: 37 years | Q12: As per Gujarat government rules | R12: Unreserved – 40 EWS – 8 SEBC – 19 SC – 7 ST – 10 | S12: Food Safety Officer (Class 3) – M.Sc Chemistry, or graduate in Food Tech / Dairy Tech / Biotech / Oil Tech / Agriculture / Veterinary / Biochemistry / Microbiology / Medicine Also required – Basic computer knowledge + Gujarati and/or Hindi | U12: First 5 years: Fixed ₹40,800 per month After 5 years: Level 5 — ₹29,200 – ₹92,300 | V12: MCQ exam (CBRT / OMR) Document verification Merit list | W12: Apply online (OJAS): https://ojas.gujarat.gov.in/ GSSSB official website: https://gsssb.gujarat.gov.in/ | AA12: No
A13: 12 | B13: Indian Army 10+2 Technical Entry Scheme (TES-57) 2026 | C13: Indian Army | D13: TES-57, July 2027 batch | E13: 90 | G13: 14 October 2026 | H13: 46338 | I13: =IF(H13="","",IF(H13<TODAY(),"Closed","Open")) | L13: Apply online starts: 14 October 2026 Last date to apply: 12 November 2026 SSB interview: As per Army schedule | M13: All candidates: No fee | O13: 16 years 6 months | P13: 19 years 6 months (as on 01 July 2027) | Q13: Between 02 Jan 2008 and 01 Jan 2011 (check notice) | R13: TES-57 (men) – 90 | S13: TES-57 – 12th with PCM, minimum 60% aggregate + JEE Main 2026 appeared | U13: During training: Stipend as per Army rules; commissioned as Lieutenant after training | V13: Shortlisting on JEE Main score SSB interview Medical examination Merit list | W13: Apply online: https://joinindianarmy.nic.in/Authentication.aspx Join Indian Army official website: https://joinindianarmy.nic.in/ | AA13: No
A14: 13 | B14: ISRO URSC Technician-B & Driver Recruitment 2026 | C14: ISRO U R Rao Satellite Centre (URSC) | D14: URSC:04:2026 | E14: 61 | G14: 24 October 2026 | H14: 46339 | I14: =IF(H14="","",IF(H14<TODAY(),"Closed","Open")) | K14: To be announced | L14: Notification released: 24 October 2026 Apply online starts: 24 October 2026 Last date to apply: 13 November 2026 Exam date: To be announced | M14: All candidates (pay first): ₹500 Refund – General / OBC / EWS: ₹400 after appearing in written test Refund – Women / SC / ST / PwBD / ESM: Full ₹500 after appearing in written test | O14: 18 years | P14: 35 years | Q14: As per government rules | R14: Technician-B Electronics Mechanic – 24 Technician-B Fitter – 8 Technician-B Electrician – 4 Technician-B Refrigeration & AC – 5 Technician-B Turner – 1 Technician-B Machinist – 2 Technician-B Motor Vehicle Mechanic – 1 Technician-B Electroplater – 1 Light Vehicle Driver-A – 3 Staff Car Driver-A – 2 Heavy Vehicle Driver-A – 10 | S14: Technician-B – 10th pass + ITI/NTC/NAC (NCVT) in the trade Light Vehicle / Staff Car Driver-A – 10th pass + LMV licence + 3 years driving experience Heavy Vehicle Driver-A – 10th pass + HMV licence + 5 years driving (3 on heavy vehicles) + PSV badge where required | U14: Technician-B: Level 3 — basic pay ₹21,700 Drivers (LVD-A, Staff Car, HVD-A): Level 2 — basic pay ₹19,900 | V14: Screening Written test Skill / driving test (qualifying) Document verification | W14: Official notification (PDF): https://www.isro.gov.in/media_isro/pdf/recruitmentNotice/2026/Oct/URSClAdvt2410_24102026.pdf ISRO official website: https://www.isro.gov.in/ | AA14: No
A15: 14 | B15: RRB NTPC 10+2 Under Graduate Level Recruitment 2026 | C15: Railway Recruitment Board (RRB) | D15: CEN 07/2026 | E15: 1688 | G15: 15 October 2026 | H15: 46341 | I15: =IF(H15="","",IF(H15<TODAY(),"Closed","Open")) | J15: 15 November 2026 | K15: To be announced | L15: Notification released: 22 September 2026 Apply online starts: 15 October 2026 Last date to apply: 15 November 2026 Last date for fee payment: 15 November 2026 Exam date: To be announced | M15: General / OBC / EWS: ₹500 (₹400 refunded after CBT-1) SC / ST / EBC / Female: ₹250 (refunded after CBT-1) | O15: 18 years | P15: 30 years | Q15: As per Railway rules | R15: Commercial cum Ticket Clerk, Train Clerk, Accounts Clerk cum Typist, Junior Clerk cum Typist – 1688 | S15: Commercial cum Ticket Clerk – 12th pass — 50% marks (Gen/OBC/EWS), pass for SC/ST/PwBD Train Clerk – 12th pass — 50% marks (Gen/OBC/EWS), pass for SC/ST/PwBD Accounts Clerk cum Typist – 12th pass + typing 30 wpm English or 25 wpm Hindi Junior Clerk cum Typist – 12th pass + typing 30 wpm English or 25 wpm Hindi | U15: Pay level: Level 2 and Level 3 (7th CPC) | V15: CBT-1 CBT-2 Typing test (where required) Document verification Medical examination | W15: Apply online: https://www.rrbapply.gov.in/ Indian Railways official website: https://indianrailways.gov.in/ | AA15: No
A16: 15 | B16: CWC Assistant Manager & Junior Executive Recruitment 2026 | C16: Central Warehousing Corporation (CWC) | D16: CWC/I-Manpower/DR/Rectt/2026/01 | E16: 327 | G16: 17 October 2026 | H16: 46341 | I16: =IF(H16="","",IF(H16<TODAY(),"Closed","Open")) | K16: To be announced | L16: Apply online starts: 17 October 2026 Last date to apply: 15 November 2026 Exam date: To be announced | M16: General / OBC / EWS: ₹1,350 SC / ST / PwBD / Female: ₹500 | O16: 18 years | P16: 28 years (as on 15 November 2026) | R16: Junior Executive (General) – 78 Junior Executive (Technical) – 78 Assistant Manager (General) – 70 Assistant Manager (Technical) – 68 Assistant Manager (Civil) – 22 Assistant Manager (Finance) – 10 Assistant Manager (Electrical) – 5 Assistant Manager (Mechanical) – 4 | S16: AM (General) – 2-year PG degree / PG diploma AM (Technical) – B.Tech in Agriculture / Food Tech / Biotech AM (Finance) – B.Com + 3 yrs experience, or CA/CMA Inter AM (Engineering) – B.E./B.Tech in Civil / Electrical / Mechanical JE (General) – Graduate + computer knowledge JE (Technical) – B.Sc in Agriculture / life sciences / Chemistry + computer knowledge | U16: Pay: See official notification | V16: Online exam Document verification | W16: Official notification (PDF): https://cwceportal.com/Careers/Guidelines/45/45_Detailed%20Advertisement_7109fe46-7e18-4b68-84a5-8b6d6708e571.pdf CWC careers (official website): https://cwceportal.com/careers | AA16: No
A17: 16 | B17: Supreme Court Court Master (Shorthand) Recruitment 2026 | C17: Supreme Court of India | D17: SCI Court Master 2026 | E17: 20 | G17: 25 October 2026 | H17: 46341 | I17: =IF(H17="","",IF(H17<TODAY(),"Closed","Open")) | K17: To be announced | L17: Apply online starts: 25 October 2026 Last date to apply: 15 November 2026 Exam date: To be announced | M17: General: ₹1,500 OBC / SC / ST / PwBD: ₹750 | O17: 30 years | P17: 45 years (as on 01 October 2026) | R17: Court Master (Shorthand) – 20 | S17: Court Master – Graduate + English shorthand 120 wpm + typing 40 wpm + 5 years experience | U17: Pay: See official notification | V17: Written / skill test Interview as per notice | W17: Official notification (PDF): https://cdnbbsr.s3waas.gov.in/s3ec0490f1f4972d133619a60c30f3559e/uploads/2026/10/2026101664.pdf Supreme Court official website: https://www.sci.gov.in/ | AA17: No
A18: 17 | B18: BEL Probationary Engineer Recruitment 2026 | C18: Bharat Electronics Limited (BEL) | D18: 17556/HR/All-India/2026 | E18: 350 | G18: 28 October 2026 | H18: 46344 | I18: =IF(H18="","",IF(H18<TODAY(),"Closed","Open")) | K18: 22 December 2026 | L18: Notification released: 28 October 2026 Apply online starts: 28 October 2026 Last date to apply: 18 November 2026 Tentative CBT date: 22 December 2026 | M18: General / EWS / OBC (NCL): ₹1,180 (incl. GST) SC / ST / PwBD / Ex-Servicemen: No fee | P18: 25 years | Q18: As per government rules | R18: Probationary Engineer (Electronics) – 200 Probationary Engineer (Mechanical) – 150 | S18: PE (Electronics) – BE/B.Tech/B.Sc Engg (4 yr) in Electronics, ECE, E&T, Communication or Telecom PE (Mechanical) – BE/B.Tech/B.Sc Engg (4 yr) in Mechanical Minimum class – First class for Gen/OBC/EWS; pass class for SC/ST/PwBD | U18: Pay scale: ₹40,000 – ₹1,40,000 | V18: Computer based test — 85% weight (125 questions, 2 hours, 0.25 negative marking) Interview — 15% weight | W18: Official notification (PDF): https://bel-india.in/wp-content/uploads/2026/10/External-Ad-2026-English-1.pdf BEL official website (apply link under Careers): https://bel-india.in/ | AA18: No
A19: 18 | B19: NPCIL Apprentice Recruitment 2026 | C19: NPCIL Narora Atomic Power Station | D19: NAPS/HRM/APPRENTICE/02/2026 | E19: 80 | G19: 29 October 2026 | H19: 46344 | I19: =IF(H19="","",IF(H19<TODAY(),"Closed","Open")) | L19: Notification released: 27 October 2026 Apply online starts: 29 October 2026 Last date to apply: 18 November 2026 | M19: Application fee: See official notification | O19: 18 years | P19: 24 / 25 / 26 years (depends on apprentice type) | Q19: 18 November 2026 | R19: Trade – Electrician – 25 Trade – Fitter – 16 Trade – Electronics Mechanic – 9 Diploma – Mechanical – 5 Diploma – Electrical – 3 Diploma – Electronics – 2 Diploma – Civil – 6 Graduate – Mechanical – 4 Graduate – Electrical – 3 Graduate – Human Resource – 3 Graduate – Finance & Accounts – 2 Graduate – Contract & Material Mgmt – 2 | S19: Trade apprentice – ITI in the relevant trade Diploma apprentice – Engineering diploma in the relevant branch Graduate apprentice (Engg) – B.E./B.Tech in the relevant branch Graduate apprentice (Non-Engg) – BBA / BA / B.Sc / B.Com as per discipline Passing year – Qualifying exam passed within 5 years of 18 Nov 2026 | U19: Trade apprentice (ITI): ₹10,560 – ₹11,040 per month Diploma apprentice: ₹10,900 per month Graduate apprentice: ₹12,300 per month | V19: Merit list based on marks in the qualifying exam | W19: NPCIL official website: https://www.npcil.nic.in/ Trade apprentice registration (apprenticeshipindia): https://www.apprenticeshipindia.gov.in/ Diploma / Graduate registration (NATS): https://www.nats.education.gov.in/ | AA19: No
A20: 19 | B20: BHEL Artisan Grade-IV Recruitment 2026 | C20: Bharat Heavy Electricals Limited (BHEL) | D20: 01/2026 | E20: 660 | G20: 21 October 2026 | H20: 46344 | I20: =IF(H20="","",IF(H20<TODAY(),"Closed","Open")) | K20: 11 December 2026 | L20: Apply online starts: 21 October 2026 Last date to apply: 18 November 2026 Exam date: 11 December 2026 | M20: General / OBC / EWS: ₹1,072 (incl. processing fee + GST) SC / ST / PwBD / Ex-Servicemen: ₹472 | P20: 27 years (as on 01 October 2026) | Q20: As per BHEL rules | R20: Fitter – 278 Welder – 104 Machinist – 101 Electrician – 90 Turner – 52 Electronics Mechanic – 23 Foundryman – 12 | S20: All trades – 10th pass + ITI in the trade — 60% marks (Gen/OBC), 55% (SC/ST) | U20: Pay: See official notification | V20: Computer based test Skill test / document verification as per notice | W20: Official notification (PDF): https://careers.bhel.in/ar_2027/Artisan_Detailed%20AD.pdf BHEL careers (official website): https://careers.bhel.in/index.jsp | AA20: No
A21: 20 | B21: Dr RMLIMS Lucknow Non-Teaching Group B & C Recruitment 2026 | C21: Dr. Ram Manohar Lohia Institute of Medical Sciences, Lucknow | D21: 78-83/Estb.-2/Rectt./Dr.RMLIMS/2026 | E21: 74 | F21: 29 Oct 2026 | G21: 19 Oct 2026 | H21: 46346 | I21: =IF(H21="","",IF(H21<TODAY(),"Closed","Open")) | J21: 20 Nov 2026 | K21: To be announced | L21: Application starts: 19 Oct 2026 Last date: 2026-11-20 Fee last date: 20 Nov 2026 Exam: To be announced | M21: General / OBC / EWS: ₹1,180 (incl. GST) SC / ST: ₹708 (incl. GST) PwBD: No fee | N21: Online | O21: 18 years | P21: 40 years | R21: Hospital Attendant Gr-II – 32 Stenographer – 30 Receptionist – 8 Programmer – 2 Medical Physicist – 1 Radiation Safety Officer – 1 | S21: Hospital Attendant Gr-II – 10th pass Stenographer – Graduate with 55% + shorthand & typing test Receptionist – Graduate + PG diploma in journalism / PR Programmer – B.E./B.Tech CS or MCA Medical Physicist – M.Sc Physics / radiological physics + internship Radiation Safety Officer – See notification | T21: UR 32 · OBC 19 · EWS 7 · SC 15 · ST 1 | U21: See official notification | W21: Recruitment page: https://www.drrmlims.ac.in/recruitment Application notice (PDF): https://www.drrmlims.ac.in/Assets/pages/recruitment/Notice_807_Online_application_window_Advt_78_83_2026.pdf | AA21: No
A22: 21 | B22: JRHMS Community Health Officer Recruitment 2026 | C22: Jharkhand Rural Health Mission Society (JRHMS) | D22: 05/2026/JRHM-CHO-Integrated | E22: 1038 | G22: 31 October 2026 | H22: 46348 | I22: =IF(H22="","",IF(H22<TODAY(),"Closed","Open")) | K22: To be announced | L22: Notification released: 28 October 2026 Apply online starts: 31 October 2026 Last date to apply: 22 November 2026 Exam date: To be announced | M22: Application fee: None (exam fee, if any, as per notice) | P22: 35 years | Q22: As per Jharkhand government rules | R22: Community Health Officer – 1038 | S22: Community Health Officer – B.Sc Nursing / Post Basic B.Sc Nursing with integrated CPCH (2016–2020 batch onwards) | U22: Monthly pay: ₹25,000 + performance incentive up to ₹15,000 | V22: Online application Eligibility and document verification Selection as per NHM guidelines | W22: Official notification (PDF): https://jrhms.jharkhand.gov.in/uploads/reports/a06bf5c1-c60c-49f8-b1dd-d18759428df7.pdf JRHMS official website / apply: https://jrhms.jharkhand.gov.in/ | AA22: No
A23: 22 | B23: UPESSC UP Headmaster Recruitment 2026 | C23: UP Education Service Selection Commission (UPESSC) | D23: 09/2026 | E23: 1172 | F23: 23 Oct 2026 | G23: 23 Oct 2026 | H23: 46348 | I23: =IF(H23="","",IF(H23<TODAY(),"Closed","Open")) | J23: 22 Nov 2026 | K23: 07 Jan 2027 | L23: Application starts: 23 Oct 2026 Last date: 2026-11-22 Fee last date: 22 Nov 2026 Exam: 07 Jan 2027 | M23: All categories: ₹1,500 | N23: Debit/credit card, net banking, UPI | O23: 30 years | P23: 62 years | Q23: As on 01 Jul 2026 | R23: Headmaster (boys’ schools) – 1037 Headmaster (girls’ schools) – 135 | S23: Headmaster (boys’ schools) – Master’s with 50% + B.Ed/B.P.Ed + 4 years teaching Headmaster (girls’ schools) – Same as above (see notification) | U23: See official notification | W23: Apply online: https://apply.upessc.org/ UPESSC official website: https://upessc.up.gov.in/ | AA23: No
A24: 23 | B24: UPESSC UP Principal (Inter College) Recruitment 2026 | C24: UP Education Service Selection Commission (UPESSC) | D24: 08/2026 | E24: 1475 | F24: 23 Oct 2026 | G24: 23 Oct 2026 | H24: 46348 | I24: =IF(H24="","",IF(H24<TODAY(),"Closed","Open")) | J24: 22 Nov 2026 | K24: 07 Jan 2027 | L24: Application starts: 23 Oct 2026 Last date: 2026-11-22 Fee last date: 22 Nov 2026 Exam: 07 Jan 2027 | M24: All categories: ₹2,000 | N24: Debit/credit card, net banking, UPI | O24: 30 years | P24: 62 years | Q24: As on 01 Jul 2026 | R24: Principal (boys’ inter colleges) – 1318 Principal (girls’ inter colleges) – 157 | S24: Principal (boys’ inter colleges) – Master’s with 50% + B.Ed + 4 years experience Principal (girls’ inter colleges) – See notification | U24: See official notification | W24: Apply online: https://apply.upessc.org/ UPESSC official website: https://upessc.up.gov.in/ | AA24: No
A25: 24 | B25: UPESSC UP TGT Teacher Recruitment 2026 | C25: UP Education Service Selection Commission (UPESSC) | D25: 07/2026 | E25: 17735 | G25: 24 October 2026 | H25: 46349 | I25: =IF(H25="","",IF(H25<TODAY(),"Closed","Open")) | K25: 23 – 24 December 2026 | L25: Apply online starts: 24 October 2026 Last date to apply: 23 November 2026 Correction last date: 26 November 2026 Exam date: 23 – 24 December 2026 | M25: General / OBC / EWS: ₹1,000 SC / ST: ₹500 PwBD: ₹300 | O25: 21 years | P25: 62 years (as on 01 July 2026) | R25: Hindi – 2791 English – 2517 Science – 2493 Social Science – 2482 Mathematics – 2349 Sanskrit – 1289 Physical Education – 849 Home Science – 798 Drawing – 775 Biology – 660 Agriculture – 248 Commerce – 134 Other subjects (see notification) – 1350 | S25: TGT (all subjects) – Graduate in the related subject + B.Ed; UP TET (Class 6–8) as per notification | U25: Pay: As per UP government TGT pay scale | V25: Written examination Answer key and result Document verification | W25: UPESSC official website / apply: https://upessc.up.gov.in/ | AA25: No
A26: 25 | B26: RRB Station Master Recruitment 2026 | C26: Railway Recruitment Board (RRB) | D26: CEN 08/2026 | E26: 1265 | G26: 27 October 2026 | H26: 46351 | I26: =IF(H26="","",IF(H26<TODAY(),"Closed","Open")) | J26: 27 November 2026 | K26: To be announced | L26: Apply online starts: 27 October 2026 Last date to apply: 25 November 2026 Last date for fee payment: 27 November 2026 Correction window: 28 November – 07 December 2026 Exam date: To be announced | M26: General / OBC / EWS: ₹500 (₹400 refunded after Stage I) SC / ST / PwBD / Female: ₹250 (refunded after Stage I) | O26: 20 years | P26: 33 years (as on 01 July 2027) | Q26: As per Railway rules | R26: RRB Mumbai (CR) – 125 RRB Jammu-Srinagar (NR) – 122 RRB Chennai (SR) – 119 RRB Thiruvananthapuram (SR) – 114 RRB Prayagraj (NCR) – 104 RRB Bengaluru (SWR) – 102 RRB Secunderabad (SCoR) – 65 RRB Bilaspur (SECR) – 52 RRB Ajmer (NWR) – 49 RRB Bhopal (WCR) – 49 Other RRBs (see notification) – 364 | S26: Station Master – Graduate in any stream | U26: Pay: As per 7th CPC — see notification | V26: CBT Stage I CBT Stage II Aptitude test Document verification Medical examination | W26: Apply online: https://www.rrbapply.gov.in/ RRB official website: https://rrb.indianrailways.gov.in/ | AA26: No
A27: 26 | B27: Supreme Court Junior Court Attendant Recruitment 2026 | C27: Supreme Court of India | E27: 130 | F27: 15 Oct 2026 | G27: 04 Nov 2026 | H27: 46351 | I27: =IF(H27="","",IF(H27<TODAY(),"Closed","Open")) | J27: 25 Nov 2026 | K27: To be announced | L27: Application starts: 04 Nov 2026 Last date: 2026-11-25 Fee last date: 25 Nov 2026 Exam: To be announced | M27: General: ₹1,500 OBC / SC / ST / PwBD: ₹750 | N27: Online only | O27: 18 years | P27: 27 years | Q27: As on 01 Oct 2026 | R27: Junior Court Attendant (Group C) – 130 | S27: Junior Court Attendant (Group C) – 10th pass | U27: See official notification | W27: Notification (PDF): https://cdnbbsr.s3waas.gov.in/s3ec0490f1f4972d133619a60c30f3559e/uploads/2026/10/2026101560.pdf Supreme Court official website: https://www.sci.gov.in/ | AA27: No
A28: 27 | B28: OPSC Scientific Officer Recruitment 2026 | C28: Odisha Public Service Commission (OPSC) | D28: Advt No. 14 of 2026-27 | E28: 89 | G28: 06 November 2026 | H28: 46352 | I28: =IF(H28="","",IF(H28<TODAY(),"Closed","Open")) | K28: To be announced | L28: Notification released: 28 October 2026 Apply online starts: 06 November 2026 Last date to apply: 26 November 2026 Exam date: To be announced | M28: General / others: ₹700 SC / ST / PwD: See notification | O28: 21 years | P28: 42 years | Q28: As per Odisha government rules | R28: Physics – 7 Ballistics – 6 Chemistry – 10 Toxicology – 13 Biology – 14 Serology – 4 DNA – 12 Forensic Psychology – 6 Cyber Forensic – 11 Document – 6 | S28: All divisions – Master’s degree in the relevant subject + ability to read, write and speak Odia | U28: Pay: Level 10, Cell 1 — ₹44,900 | V28: Paper I — 100 marks (English, GK, reasoning) Paper II — 300 marks (subject) Viva voce — 50 marks Negative marking: 25% per wrong answer | W28: OPSC official website / apply: https://www.opsc.gov.in/ | AA28: No
A29: 28 | B29: UPPSC RO / ARO Recruitment 2026 | C29: Uttar Pradesh Public Service Commission (UPPSC) | D29: RO/ARO 2026 | E29: 501 | G29: 26 October 2026 | H29: 46352 | I29: =IF(H29="","",IF(H29<TODAY(),"Closed","Open")) | K29: To be announced | L29: Apply online starts: 26 October 2026 Last date to apply: 26 November 2026 Correction date: 03 December 2026 Exam date: To be announced | M29: General / OBC / EWS: ₹125 SC / ST: ₹65 PwBD: ₹25 | O29: 21 years | P29: 40 years (as on 01 July 2026) | R29: Assistant Review Officer, UP Secretariat – 261 Review Officer, UP Secretariat – 122 Assistant Review Officer, Advocate General Office – 45 Review Officer (Accounts), UP Secretariat – 31 Assistant Review Officer, UPPSC – 21 Other RO / ARO posts – See notification (total 501) | S29: Review Officer – Graduate in any stream Review Officer (Accounts) – B.Com + DOEACC O Level Assistant Review Officer – Graduate + O Level + Hindi typing 25 wpm | U29: Pay: See official notification | V29: Prelims exam Mains exam Typing test (ARO) Document verification | W29: Apply online (UPPSC notifications): https://uppsc.up.nic.in/CandidatePages/Notifications.aspx UPPSC official website: https://uppsc.up.nic.in/ | AA29: No
A30: 29 | B30: UPSSSC Lower Subordinate (Inter Level) Mains Recruitment 2026 | C30: UP Subordinate Services Selection Commission (UPSSSC) | D30: 26-Exam/2026 | E30: 1784 | F30: 16 Oct 2026 | G30: 10 Nov 2026 | H30: 46357 | I30: =IF(H30="","",IF(H30<TODAY(),"Closed","Open")) | J30: 01 Dec 2026 | K30: To be announced | L30: Application starts: 10 Nov 2026 Last date: 2026-12-01 Fee last date: 01 Dec 2026 Exam: To be announced | M30: All categories: ₹25 | N30: Debit/credit card, net banking, UPI | O30: 18 years | P30: 40 years | Q30: Valid UPSSSC PET score required | R30: Village Development Officer (Social Welfare) – 525 Village Development Officer – 508 Commercial Tax Collection Amin – 235 Land Amin – 187 Social Welfare Supervisor – 137 Storekeeper & Clerk – 118 Cooperative Agriculture Supervisor – 50 Tabulator – 14 House Mother – 5 Other posts – 5 | S30: Village Development Officer (Social Welfare) – 12th pass Village Development Officer – 12th pass Commercial Tax Collection Amin – 12th pass Land Amin – 12th pass Social Welfare Supervisor – 12th pass Storekeeper & Clerk – 12th pass Cooperative Agriculture Supervisor – 12th pass Tabulator – 12th pass House Mother – 12th pass Other posts – 12th pass | T30: UR 840 · OBC 448 · EWS 144 · SC 326 · ST 26 | U30: See official notification | W30: Notifications / apply: https://upsssc.gov.in/AllNotifications.aspx UPSSSC official website: https://upsssc.gov.in/ | AA30: No
A31: 30 | B31: JKSSB Junior Engineer (Civil) Recruitment 2026 | C31: J&K Services Selection Board (JKSSB) | D31: 11 of 2026 | E31: 458 | G31: 30 November 2026 | H31: 46387 | I31: =IF(H31="","",IF(H31<TODAY(),"Closed","Open")) | K31: To be announced | L31: Notification released: 23 October 2026 Apply online starts: 30 November 2026 Last date to apply: 31 December 2026 Exam date: To be announced | M31: Open merit / others: ₹600 SC / ST-1 / ST-2 / EWS / PwBD: ₹500 | P31: 40 years | Q31: As per J&K rules | R31: Junior Engineer (Civil) – 458 | S31: Junior Engineer (Civil) – 3-year Diploma in Civil Engg, or B.E./B.Tech Civil, or AMIE (A & B) | U31: Pay: Level 6 — ₹35,400 – ₹1,12,400 | V31: Objective written / OMR exam (English) Document verification | W31: Official notification (PDF): https://jkssb.nic.in/Pdf/Advertisement_11OF2026_27102026.pdf JKSSB official website / apply: https://www.jkssb.nic.in/ | AA31: No
A32: 31 | B32: GRSE Journeyman & Driver Recruitment 2026 | C32: Garden Reach Shipbuilders & Engineers Limited (GRSE) | D32: 2026/05 (J&OP) | E32: 58 | F32: 30 Oct 2026 | G32: 30 Oct 2026 | H32: 46354 | I32: Open | J32: 30 Nov 2026 (fee payment verification) | K32: To be announced | L32: Application starts: 30 Oct 2026 Last date: 2026-11-28 Fee payment verification by: 30 Nov 2026 Exam: To be announced | M32: General / OBC / EWS: ₹472 SC / ST / PwBD / GRSE internal candidates: No fee | N32: Online only | O32: Not specified | P32: Journeyman: 26 years; Driver (Vehicle): 32 years | Q32: As on 01 October 2026; relaxation per rules (max after relaxation 56 years) | R32: Electrician – 8 Electronic Mechanic – 6 Painter – 6 Fitter – 6 Structural Fitter – 4 GRP/FRP Worker – 4 Pipe Fitter – 4 Rigger – 4 Machine Operator – 3 Carpenter – 2 Crane Operator – 2 Diesel Mechanic – 2 Driver Material Handling – 2 Welder – 2 Driver (Vehicle) – 3 | S32: Journeyman – 10th pass + relevant NAC/NTC trade certificate Driver (Vehicle) – 10th pass + Commercial LMV licence + 6 years driving experience | T32: Journeyman (55): UR 23 · SC 12 · ST 3 · OBC 10 · EWS 7 Driver (3): UR 2 · OBC 1 | U32: Journeyman stipend (2-yr training) – ₹24,000/month (Yr1), ₹26,000/month (Yr2) Driver (Vehicle) – Skilled Grade-III, ₹20,110–₹70,390/month | V32: Written examination Document verification Practical trade test Physical efficiency test (select posts) Medical examination | W32: Apply online: https://jobapply.in/GRSE2026Journeyman/Default.aspx Detailed advertisement (PDF): https://jobapply.in/GRSE2026Journeyman/adv_eng.pdf GRSE official website: https://www.grse.in/ | AA32: No
A33: 32 | B33: AEES Principal, PGT, TGT, PRT & Other Teaching Recruitment 2026 | C33: Atomic Energy Education Society (AEES) | D33: 01/2026 | E33: 254 | F33: 30 Oct 2026 | G33: 02 Nov 2026 | H33: 46348 | I33: Open | J33: 22 Nov 2026 | K33: To be announced | L33: Application starts: 02 Nov 2026 Last date: 2026-11-22 Fee last date: 22 Nov 2026 Exam: To be announced | M33: General / OBC / EWS: ₹1,000 (₹750 application + ₹250 processing) Women / SC / ST / PwBD / Ex-Servicemen: ₹250 (processing only) | N33: Online | O33: 18 years | P33: Principal 50; Vice-Principal 45; PGT 40; TGT/Librarian 35; PRT/PRT Music/Balvatika 30 (years) | Q33: As on 22 November 2026; relaxation SC/ST +5, OBC +3, Women +10, PwBD (General) +10 | R33: Principal – 4 Vice-Principal – 1 Post Graduate Teacher (PGT) – 27 Trained Graduate Teacher (TGT) – 102 Librarian – 13 Primary Teacher (PRT) – 89 PRT Music – 10 Balvatika Teacher – 8 | S33: Principal – Master's (50%) + B.Ed + experience as Principal/VP/PGT PGT – Postgraduate degree (50%) + B.Ed, no CTET required TGT – Bachelor's with subject combination + B.Ed + CTET Paper-II Librarian – Bachelor's in Library Science (50%) PRT – 12th pass (50%) + D.El.Ed/B.El.Ed + CTET Paper-I PRT Music – 12th pass + Bachelor's in Music Balvatika Teacher – 12th pass + Nursery/ECE diploma or B.Ed (Nursery) | T33: UR 112 · OBC-NCL 68 · SC 33 · ST 16 · EWS 25 (PwBD 12, horizontal) | U33: Principal – Level 12, ₹78,800–₹2,09,200 Vice-Principal – Level 10, ₹56,100–₹1,77,500 PGT – Level 8, ₹47,600–₹1,51,100 TGT/Librarian – Level 7, ₹44,900–₹1,42,400 PRT/PRT Music/Balvatika – Level 6, ₹35,400–₹1,12,400 | V33: Computer Based Test (CBT), no negative marking Interview (Principal/VP only, 50% CBT + 50% interview) Qualifying skill test (other posts) Document verification Medical fitness examination | W33: Apply online: https://aees.onlineregistrationforms.com AEES official website: https://www.aees.gov.in/ | AA33: No
A34: 33 | B34: RITES Assistant Manager (Mechanical) Recruitment 2026 | C34: Rail India Technical and Economic Service (RITES) | D34: CL/09/26, CL/10/26, CL/11/26 | E34: 27 | F34: 30 Oct 2026 | G34: 30 Oct 2026 | H34: 46346 | I34: Open | J34: 20 Nov 2026 | K34: 29 Nov 2026 | L34: Application starts: 30 Oct 2026 Last date: 2026-11-20 Fee last date: 20 Nov 2026 Written test: 29 Nov 2026 | M34: General / OBC: ₹600 + taxes EWS / SC / ST / PwBD: ₹300 + taxes (refunded after written test/interview participation) | N34: Online | O34: Not specified | P34: 40 years | Q34: As on 20 November 2026; SC/ST +5, OBC-NCL +3, PwBD +10 (over category relaxation) | R34: AM-Mechanical-I (CL/09/26) – 14 AM-Mechanical-II (CL/10/26) – 10 AM-Mechanical-III (CL/11/26) – 3 | S34: AM-Mechanical-I – Diploma/B.Tech (Mechanical) + 8/2 years QA-QC-Testing experience AM-Mechanical-II – Same + ASNT/ISNT Level-II (UT) AM-Mechanical-III – Same + ASNT/ISNT Level-II (MPT) | T34: AM-I: UR 8, EWS 1, OBC 3, SC 1, ST 1 AM-II: UR 6, EWS 1, OBC 2, SC 1 AM-III: UR 3 | U34: Basic ₹24,258; Gross ₹38,085 per month (contract, lumpsum basis) | V34: Written test (125 objective questions, 2.5 hours, no negative marking) Interview Document verification Medical examination | W34: Apply online / careers: https://rites.com/Career Official notification (PDF): https://rites.com/Upload/Career/Advertisement_for_CL-09-11_26_pdf-2026-Oct-30-14-18-27.pdf RITES official website: https://www.rites.com/ | AA34: No
A35: 34 | B35: Delhi University Assistant Recruitment 2026 | C35: University of Delhi (DU) | D35: R&P/325/2026 | E35: 215 | F35: 29 Oct 2026 | G35: 29 Oct 2026 | H35: 46345 | I35: Open | J35: 19 Nov 2026 | K35: To be announced | L35: Application starts: 29 Oct 2026 Last date: 2026-11-19 (or 2 weeks from Employment News publication, whichever is later) Exam: To be announced | M35: General / UR: ₹1,000 OBC (NCL) / EWS / Female: ₹800 SC / ST / PwBD: ₹600 | N35: Online | O35: Not specified | P35: 32 years | Q35: As on application closing date; relaxation per Central Government orders | R35: Assistant – 215 | S35: Assistant – Bachelor's degree + 2 years' experience as Junior Assistant or equivalent + English typing 35 wpm or Hindi typing 30 wpm + computer proficiency | T35: UR 164 · SC 33 · ST 18 · PwBD (Visual Impairment) 1 (horizontal) | U35: Level 4, 7th CPC | V35: Preliminary test (100 MCQs, 200 marks, 0.5 negative marking) Main examination (descriptive, 200 marks) Skill test (typing & computer, qualifying) | W35: Recruitment notice: https://www.du.ac.in/ DU official website: https://www.du.ac.in/ | AA35: No
A36: 35 | B36: CWC Chief Draughtsman Recruitment 2026 (Deputation) | C36: Central Water Commission (CWC), Ministry of Jal Shakti | D36: Vacancy Circular 01/2026 | E36: 39 | F36: 27 Oct 2026 | G36: 27 Oct 2026 | H36: 46384 | I36: Open | J36: Not applicable | K36: Not applicable (deputation; CV screening by Selection Committee) | L36: Application starts: 27 Oct 2026 Last date: within 60 days of Employment News publication (approx. 2026-12-28) | M36: Not specified in notification | N36: Not applicable (offline, deputation route) | O36: Not specified | P36: 56 years | Q36: As on closing date for applications | R36: Chief Draughtsman – 39 (across CWC HQ and 16 field/basin organisations) | S36: Chief Draughtsman – Diploma in Civil/Mechanical Engineering + 3 years' relevant experience; on deputation from an analogous post or 5 years in a Level-6 post | U36: Level-7, ₹44,900 – ₹1,42,400 per month | V36: Screening of CV, qualifications and experience by Selection Committee | W36: CWC official website: https://cwc.gov.in/ Application address: Under Secretary, Establishment-X, CWC, Sewa Bhawan, R.K. Puram, New Delhi | AA36: No
A37: 36 | B37: KEA FDA SDA Recruitment 2026 | C37: Karnataka Examinations Authority (KEA) | D37: RPC & Kalyana Karnataka notifications (29 Oct 2026) | E37: 5431 | F37: 29 Oct 2026 | G37: 30 Oct 2026 | H37: 46351 | I37: Open | J37: 26 Nov 2026 | K37: 08, 09, 10, 16, 17 January 2027 | L37: Application starts: 30 Oct 2026 Last date: 2026-11-25 Fee last date: 26 Nov 2026 Exam: 08–17 January 2027 | M37: General Merit: ₹750 Reserved categories: ₹500 Special concession: ₹250 | N37: Online | O37: 18 years | P37: General Merit 40; Category 2A/2B/3A/3B 43; SC/ST/Category-1 45 (years) | Q37: As on application date | R37: Degree-level RPC – 2163 PUC-level RPC – 2070 Degree-level Kalyana Karnataka – 563 PUC-level Kalyana Karnataka – 635 | S37: PUC-level (SDA) – 2nd PUC (12th pass) or equivalent Degree-level (FDA) – Recognised Bachelor's degree or equivalent | U37: PUC-level – ₹34,100–₹67,600 Degree-level – ₹44,425–₹83,700 Supervisory posts – ₹49,050–₹92,500+ | V37: Written examination (2 papers, 100 marks each, 0.25 negative marking) Document verification | W37: Apply online: https://cetonline.karnataka.gov.in/kea KEA official website: https://cetonline.karnataka.gov.in/kea | AA37: No
A38: 37 | B38: India Post Staff Car Driver Recruitment 2026 | C38: Department of Posts, Ministry of Communications (Mail Motor Service, Chennai) | E38: 24 | F38: 29 Oct 2026 | G38: Not stated | H38: 46356 | I38: Open | J38: 30 Nov 2026 | K38: To be announced | L38: Last date: 2026-11-30 (5:00 PM) Fee last date: 30 Nov 2026 Exam: To be announced | M38: General / OBC / EWS: ₹100 Women / SC / ST: No fee | N38: Offline (e-payment at computerised post office) | O38: 18 years | P38: UR/EWS 27; OBC 30; SC/ST 32 (years) | Q38: As on 30 November 2026; relaxation for govt. servants up to 40, Ex-Servicemen service-based | R38: Staff Car Driver (Ordinary Grade) – 24 (Central Region 1, MM Region 15, Southern Region 2, Western Region 6) | S38: Staff Car Driver – 10th pass + valid LMV & HMV licence + minimum 3 years driving experience on light and heavy vehicles | T38: UR 13 · SC 3 · OBC 7 · EWS 1 (2 posts reserved for Ex-Servicemen, horizontal) | U38: Level 2 (7th CPC), ₹19,900 – ₹63,200 | V38: Theory examination (80 MCQs, 80 marks, 90 minutes) Practical driving test (20 marks) | W38: Notification (PDF): https://www.indiapost.gov.in/api/documents/file/100aafo2s64m0fy8p35t6z0iqrq3bvgv0sj5u0eiq33cu8h3a0kc0fh8h35s2f India Post official website: https://www.indiapost.gov.in/ Apply offline: Senior Manager, Mail Motor Service, Chennai (Speed Post only) | AA38: No
A39: 38 | B39: India Post Skilled Artisan Recruitment 2026 | C39: Department of Posts, Ministry of Communications (Mail Motor Services, Kolkata) | D39: MMG/36/Sk. Artisan/DR/II/95 | E39: 19 | F39: 29 Oct 2026 | G39: Not stated | H39: 46356 | I39: Open | J39: 30 Nov 2026 | K39: To be announced (trade test) | L39: Corrigendum released: 29 Oct 2026 Last date: 2026-11-30 (5:00 PM) Trade test: To be announced | M39: Not specified in the corrigendum | N39: Offline | O39: 18 years | P39: 30 years (UR) | Q39: As on 01 July 2018; SC/ST +5, OBC-NCL +3, govt. servants up to 40, Ex-Servicemen service-based | R39: MV Mechanic – 8 MV Electrician – 4 Tyreman – 2 Blacksmith – 2 Painter – 1 Upholsterer – 1 Carpenter & Joiner – 1 | S39: Skilled Artisan – Trade certificate from a government-recognised technical institution, OR 8th pass + 1 year trade experience; MV Mechanic also needs a valid HMV licence | T39: MV Mechanic: UR 4, SC 2, ST 1, OBC 1 MV Electrician: UR 2, SC 1, OBC 1 Tyreman: UR 1, OBC 1 Blacksmith: UR 1, SC 1 Painter: UR 1 Upholsterer: UR 1 Carpenter & Joiner: OBC 1 | U39: Level 2 (7th CPC), ₹19,900 – ₹63,200 | V39: Scrutiny and shortlisting Competitive trade test | W39: Notification (PDF): https://www.indiapost.gov.in/api/documents/file/10391xe2ox8w0is613k9jr369dy34fsw0s5ca3h16z08vuz04nku0gw9f35snp India Post official website: https://www.indiapost.gov.in/ Apply offline: Senior Manager, Mail Motor Services, Kolkata (Speed Post only) | AA39: No
A40: 39 | B40: Goa Samagra Shiksha Instructor (NSQF Sectors) Recruitment 2026 | C40: Goa Samagra Shiksha | D40: GSS/WII/99/2026-27/3986 | E40: 41 | F40: 30 Oct 2026 | G40: Walk-in (no online application) | H40: Walk-in interview: 05–06 November 2026 | I40: Open | J40: Not applicable | K40: Walk-in interview: 05–06 November 2026 | L40: Advertisement: 30 Oct 2026 Walk-in interview: 05–06 Nov 2026 Contract end: 31 Mar 2027 | M40: Not specified | N40: Not applicable (walk-in) | O40: Not specified | P40: Not specified | Q40: As per Govt. norms | R40: Tourism & Hospitality – 8 Electronics – 6 Agriculture – 6 Healthcare – 4 Retail – 3 Logistics – 3 Automobile – 3 Media & Entertainment – 2 Construction – 2 BFSI – 2 Telecommunication – 1 Plumbing – 1 | S40: Konkani knowledge essential for all posts; sector-specific diploma/degree + experience (e.g. Tourism & Hospitality – Hotel Management diploma/degree + 5 yrs experience; Healthcare – GNM/B.Sc Nursing + 2–3 yrs experience) | U40: ₹20,000 per month (consolidated), contract till 31 March 2027 | V40: Walk-in interview with original document verification | W40: Notification (PDF): https://scert.goa.gov.in/wp-content/uploads/2026/10/GSS-Advt-30.10.2026.pdf | AA40: No
...

Sheet Vacancy & Eligibility
A1: Job | B1: Post / trade / subject | C1: Vacancies | D1: Eligibility (short)
A2: Indian Army TGC-145 (July 2027 batch) Online Form 2026 | B2: Civil / Building Construction | C2: 8 | D2: B.E./B.Tech in branch (final-year can apply)
A3: Indian Army TGC-145 (July 2027 batch) Online Form 2026 | B3: Computer Science / IT / M.Sc CS | C3: 6 | D3: B.E./B.Tech or M.Sc in branch
A4: Indian Army TGC-145 (July 2027 batch) Online Form 2026 | B4: Mechanical / Production / Automobile | C4: 6 | D4: B.E./B.Tech in branch
A5: Indian Army TGC-145 (July 2027 batch) Online Form 2026 | B5: Electronics & Telecom | C5: 6 | D5: B.E./B.Tech in branch
A6: Indian Army TGC-145 (July 2027 batch) Online Form 2026 | B6: Electrical / EEE | C6: 2 | D6: B.E./B.Tech in branch
A7: Indian Army TGC-145 (July 2027 batch) Online Form 2026 | B7: Misc. engineering streams | C7: 2 | D7: B.E./B.Tech in branch
A8: NTA UGC NET December 2026 Online Form | B8: JRF / Assistant Professor / PhD admission | C8: — | D8: Master’s degree with 55% (50% for reserved)
A9: LIC Housing Finance Apprentice Recruitment 2026 | B9: Apprentice | C9: 232 | D9: Graduate in any stream
A10: BPSC School Teacher TRE 4.0 Recruitment 2026 | B10: Primary teacher (Class 1–5) | C10: 3847 | D10: 12th + D.El.Ed/B.El.Ed + STET/CTET Paper I
A11: BPSC School Teacher TRE 4.0 Recruitment 2026 | B11: Middle school teacher (Class 6–8) | C11: 8563 | D11: Graduate + D.El.Ed/B.Ed + CTET/STET Paper II
A12: BPSC School Teacher TRE 4.0 Recruitment 2026 | B12: Secondary teacher (Class 9–10) | C12: 4370 | D12: Graduate/PG in subject + B.Ed + STET
A13: BPSC School Teacher TRE 4.0 Recruitment 2026 | B13: Senior secondary teacher (Class 11–12) | C13: 16540 | D13: PG in subject + B.Ed + STET
A14: DSSSB Delhi District Courts Various Post Recruitment 2026 | B14: Personal Assistant (District Courts) | C14: 189 | D14: See Eligibility column on Latest Jobs
A15: DSSSB Delhi District Courts Various Post Recruitment 2026 | B15: Junior Judicial Assistant (District Courts) | C15: 151 | D15: See Eligibility column on Latest Jobs
A16: DSSSB Delhi District Courts Various Post Recruitment 2026 | B16: Peon / Orderly / Dak Peon (District Courts) | C16: 139 | D16: See Eligibility column on Latest Jobs
A17: DSSSB Delhi District Courts Various Post Recruitment 2026 | B17: Process Server (District Courts) | C17: 91 | D17: See Eligibility column on Latest Jobs
A18: DSSSB Delhi District Courts Various Post Recruitment 2026 | B18: Senior Personal Assistant (District Courts) | C18: 27 | D18: See Eligibility column on Latest Jobs
A19: DSSSB Delhi District Courts Various Post Recruitment 2026 | B19: Junior Judicial Assistant (Family Courts) | C19: 23 | D19: See Eligibility column on Latest Jobs
A20: DSSSB Delhi District Courts Various Post Recruitment 2026 | B20: Personal Assistant (Family Courts) | C20: 17 | D20: See Eligibility column on Latest Jobs
... A141: UPPSC RO / ARO Recruitment 2026 | B141: Assistant Review Officer, UPPSC | C141: 21 | D141: See Eligibility column on Latest Jobs
A142: UPPSC RO / ARO Recruitment 2026 | B142: Other RO / ARO posts | C142: See notification (total 501) | D142: See Eligibility column on Latest Jobs
A143: UPSSSC Lower Subordinate (Inter Level) Mains Recruitment 2026 | B143: Village Development Officer (Social Welfare) | C143: 525 | D143: 12th pass
A144: UPSSSC Lower Subordinate (Inter Level) Mains Recruitment 2026 | B144: Village Development Officer | C144: 508 | D144: 12th pass
A145: UPSSSC Lower Subordinate (Inter Level) Mains Recruitment 2026 | B145: Commercial Tax Collection Amin | C145: 235 | D145: 12th pass
A146: UPSSSC Lower Subordinate (Inter Level) Mains Recruitment 2026 | B146: Land Amin | C146: 187 | D146: 12th pass
A147: UPSSSC Lower Subordinate (Inter Level) Mains Recruitment 2026 | B147: Social Welfare Supervisor | C147: 137 | D147: 12th pass
A148: UPSSSC Lower Subordinate (Inter Level) Mains Recruitment 2026 | B148: Storekeeper & Clerk | C148: 118 | D148: 12th pass
A149: UPSSSC Lower Subordinate (Inter Level) Mains Recruitment 2026 | B149: Cooperative Agriculture Supervisor | C149: 50 | D149: 12th pass
A150: UPSSSC Lower Subordinate (Inter Level) Mains Recruitment 2026 | B150: Tabulator | C150: 14 | D150: 12th pass
A151: UPSSSC Lower Subordinate (Inter Level) Mains Recruitment 2026 | B151: House Mother | C151: 5 | D151: 12th pass
A152: UPSSSC Lower Subordinate (Inter Level) Mains Recruitment 2026 | B152: Other posts | C152: 5 | D152: 12th pass
A153: JKSSB Junior Engineer (Civil) Recruitment 2026 | B153: Junior Engineer (Civil) | C153: 458 | D153: 3-year Diploma in Civil Engg, or B.E./B.Tech Civil, or AMIE (A & B)

Sheet Admit Card
A1: # | B1: Title | C1: Organisation | D1: Advt. no. | E1: Total posts | F1: Key dates | G1: Login needed | H1: Next stages | I1: Fee | J1: Eligibility | K1: Exam pattern | L1: Marking / notes | M1: Main topics | N1: Official links | O1: YOUR short info (write) | P1: Written?
A2: 1 | B2: SSC CGL Tier-I Admit Card 2026 | C2: Staff Selection Commission (SSC) | E2: 12256 | F2: Tier-I exam city details: 21 September 2026 Admit card released: 27 September 2026 Tier-I exam: 30 September – 30 October 2026 Tier-II exam: December 2026 (tentative) | G2: Registration number / user ID Password or date of birth | N2: SSC candidate login (admit card): https://ssc.gov.in/login Tier-I exam city notice: https://ssc.gov.in/api/attachment/uploads/masterData/NoticeBoards/cgle_2026_city_live_21092026.pdf Exam date notice: https://ssc.gov.in/api/attachment/uploads/masterData/NoticeBoards/Important%20Notice%202026_cgle_2026_12092026.pdf SSC official website: https://ssc.gov.in/ | P2: No
A3: 2 | B3: NVS JNVST Class 6 Admit Card 2027 | C3: Navodaya Vidyalaya Samiti (NVS) | F3: Admit card released: 28 October 2026 Selection test date: 28 November 2026 Result: To be announced | G3: Registration number Date of birth | H3: Selection test Merit list Document check and admission | N3: Download admit card: https://cbseitms.rcil.gov.in/nvs/AdminCard/Admit2027Card Forgot registration number: https://cbseitms.rcil.gov.in/nvs/ChildernPrint/findRegistrationno Prospectus (PDF): https://cbseitms.rcil.gov.in/nvs/assets/pdf/Final_Prospectus_2027.pdf NVS admission portal: https://cbseitms.rcil.gov.in/nvs/ | P3: No
A4: 3 | B4: Bank of Baroda Specialist Officer (SO) Admit Card 2026 | C4: Bank of Baroda | D4: BOB/HRM/REC/ADVT/2026/15 | E4: 206 | F4: Admit card released: 24 October 2026 Online exam: 01 November 2026 Result: To be announced | G4: Registration / roll number Password or date of birth | H4: Online test Psychometric test / personal interview Final merit list | N4: Call letter notice (PDF): https://bankofbaroda.bank.in/-/media/Project/BOB/CountryWebsites/India/Career/2026/26-10/Online-Examination-Digital-23-34.pdf Exam date notice (PDF): https://bankofbaroda.bank.in/-/media/Project/BOB/CountryWebsites/India/Career/2026/26-10/Notification-for-Online-Examination-Digital-19-20.pdf Bank of Baroda careers: https://bankofbaroda.bank.in/career/current-opportunities | P4: No
A5: 4 | B5: AAI Junior Executive & Manager Admit Card 2026 | C5: Airports Authority of India (AAI) | D5: 12/2026/CHQ/DR-CBT | E5: 389 | F5: Admit card released: 14 October 2026 Exam dates: 21 & 26 October 2026 Result: To be announced | G5: Registration number Date of birth / password | H5: Computer based test Document verification Further tests / interview as per post | N5: Exam notice (PDF): https://www.aai.aero/sites/default/files/examdashboard_pressnote/Exam%20Notice.pdf AAI careers page: https://www.aai.aero/en/careers/recruitment | P5: No
